Workbook

Sheet VO1
A4: CONTRACT VARIATION
A6: PROJECT: | B6: ARCO | F6: Date: | G6: 13/08/2025
A7: NAME: | B7: Welink Construction | F7: Site Instruction / Ref:
A8: SITE ADDRESS: | B8: 22 - 24 Hood St, Subiaco
A9: JOB No: | B9: 1504
B11: VO1 - Wet Fire Variation to Ground Floor
A12: Item | B12: Description | F12: Cost | G12: Credit
B13: Additional works from Design to IFC Drawings from Forth Engineering | C13: Qty | D13: Unit | E13: Rate ($)
A14: 1 | B14: Relocation of Fire Hydrant - additional Hydrant and Enclosure | C14: 1 | D14: item | E14: 31345 | F14: 31345
A15: 2 | B15: Additional pipework and sleeves as per IFC drawings | C15: 1 | D15: item | E15: 15678 | F15: 15678
A16: 3 | B16: Earthwork allowance - detail excavation, refill and for additional works | C16: 1 | D16: item | E16: 9860 | F16: 9860
A17: 4 | B17: 600x600x600mm concrete pad footing allowed for fire hydrant installation | C17: 1 | D17: item | E17: 2347 | F17: 2347
A18: 5 | B18: Electrical Attendance and Builders Works | C18: 1 | D18: item | E18: 5460 | F18: 5460
F19: =C19*E19 -> 0
B21: NB - no additional traffic bollards and signage included
A23: SUB TOTAL | F23: =SUM(F13:F22) -> 64690 | G23: =SUM(G13:G22) -> 0
A24: NETT VARIATION COST | F24: =F23-G23 -> 64690
A25: MARGIN AND OVERHEAD COSTS (10%) | F25: =F24*0.1 -> 6469
A26: VARIATION COST EXCLUDING GST | F26: =F24+F25 -> 71159
A27: GST | F27: =F26*0.1 -> 7115.9
A28: TOTAL INCLUDING GST | F28: =F26+F27 -> 78274.9
F31: Variation Raised By:
F32: AC
A34: ACCEPTED FOR AND ON BEHALF OF CLIENT: | F34: Authorised By:

Sheet VO2
A4: CONTRACT VARIATION
A6: PROJECT: | B6: ARCO | F6: Date: | G6: 45882
A7: NAME: | B7: Welink Construction | F7: Site Instruction / Ref:
A8: SITE ADDRESS: | B8: 22 - 24 Hood St, Subiaco
A9: JOB No: | B9: 1504
B11: VO2 - Upgrade to 50 dia supply Water to Ground floor
A12: Item | B12: Description | F12: Cost | G12: Credit
B13: Additional from Design to IFC from Forth Engineering | C13: Qty | D13: Unit | E13: Rate ($)
A15: 1 | B15: Upgrade to 50 dia supply Water to Ground Floor | C15: 1 | D15: item | E15: 23450 | F15: =E15*C15 -> 23450
F16: =E16*C16 -> 0
A18: SUB TOTAL | F18: =SUM(F13:F17) -> 23450 | G18: =SUM(G13:G17) -> 0
A19: NETT VARIATION COST | F19: =F18-G18 -> 23450
A20: MARGIN AND OVERHEAD COSTS (10%) | F20: =F19*0.1 -> 2345
A21: VARIATION COST EXCLUDING GST | F21: =F19+F20 -> 25795
A22: GST | F22: =F21*0.1 -> 2579.5
A23: TOTAL INCLUDING GST | F23: =F21+F22 -> 28374.5
F26: Variation Raised By:
F27: AC
A29: ACCEPTED FOR AND ON BEHALF OF CLIENT: | F29: Authorised By:

Sheet VO3
A4: CONTRACT VARIATION - ESTIMATE
A6: PROJECT: | B6: ARCO | F6: Date: | G6: 45882
A7: NAME: | B7: Welink Construction | F7: Site Instruction / Ref:
A8: SITE ADDRESS: | B8: 22 - 24 Hood St, Subiaco
A9: JOB No: | B9: 1504
B11: VO3 - Earthworks - additional backfill & testing
A12: Item | B12: Description | F12: Cost | G12: Credit
C13: Qty | D13: Unit | E13: Rate ($)
A14: 1 | B14: Additional backfill & testing - Latent soil conditions was so bad that new sand had to be brough in and compacted for the Pile Mat | C14: 1 | D14: ITEM | E14: 69800 | F14: =C14*E14 -> 69800
F15: =C15*E15 -> 0
B16: Remove Contaminated Dirt/New Spoil/Additional Compaction
A18: SUB TOTAL | F18: =SUM(F13:F17) -> 69800 | G18: =SUM(G13:G17) -> 0
A19: NETT VARIATION COST | F19: =F18-G18 -> 69800
A20: MARGIN AND OVERHEAD COSTS (10%) | F20: =F19*0.1 -> 6980
A21: VARIATION COST EXCLUDING GST | F21: =F19+F20 -> 76780
A22: GST | F22: =F21*0.1 -> 7678
A23: TOTAL INCLUDING GST | F23: =F21+F22 -> 84458
F26: Variation Raised By:
F27: AC
A29: ACCEPTED FOR AND ON BEHALF OF CLIENT: | F29: Authorised By:

Sheet VO4
A4: CONTRACT VARIATION
A6: PROJECT: | B6: ARCO | F6: Date: | G6: 45882
A7: NAME: | B7: Welink Construction | F7: Site Instruction / Ref:
A8: SITE ADDRESS: | B8: 22 - 24 Hood St, Subiaco
A9: JOB No: | B9: 1504
B11: VO4 - Site Amenities - Lease
A12: Item | B12: Description | F12: Cost | G12: Credit
C13: Qty | D13: Unit | E13: Rate ($)
A14: 1 | B14: Site office land rental | C14: 3 | D14: Years | E14: 100000 | F14: =SUM(E14*C14) -> 300000
F15: =C15*E15 -> 0
A18: SUB TOTAL | F18: =SUM(F13:F17) -> 300000 | G18: =SUM(G13:G17) -> 0
A19: NETT VARIATION COST | F19: =F18-G18 -> 300000
A20: MARGIN AND OVERHEAD COSTS (10%) | F20: =F19*10% -> 30000
A21: VARIATION COST EXCLUDING GST | F21: =F19+F20 -> 330000
A22: GST | F22: =F21*0.1 -> 33000
A23: TOTAL INCLUDING GST | F23: =F21+F22 -> 363000
F26: Variation Raised By:
F27: AC
A29: ACCEPTED FOR AND ON BEHALF OF CLIENT: | F29: Authorised By:

Sheet VO5
A4: CONTRACT VARIATION
A6: PROJECT: | B6: ARCO | F6: Date: | G6: 45882
A7: NAME: | B7: Welink Construction | F7: Site Instruction / Ref:
A8: SITE ADDRESS: | B8: 22 - 24 Hood St, Subiaco
A9: JOB No: | B9: 1504
B11: VO5 - Fire Services IFC Updates
A12: Item | B12: Description | F12: Cost | G12: Credit
B13: Additional Fire pipework required from Forth Engineering from Design to IFC | C13: Qty | D13: Unit | E13: Rate ($)
A14: 1 | B14: Fire Services Update to IFC Additional 70m 100m pipework Pump Exhaust to go from basement to roof approx. 30m 24 x new ceiling space sprinklers 34 x new exposed sprinklers 24 x car stacker heads – count as exposed similar pricing 12 water shields – count as exposed similar pricing | C14: 1 | D14: item | E14: 16590 | F14: =SUM(E14*1) -> 16590
A17: SUB TOTAL | F17: =SUM(F13:F16) -> 16590 | G17: =SUM(G13:G16) -> 0
A18: NETT VARIATION COST | F18: =F17-G17 -> 16590
A19: MARGIN AND OVERHEAD COSTS (10%) | F19: =F18*10% -> 1659
A20: VARIATION COST EXCLUDING GST | F20: =F18+F19 -> 18249
A21: GST | F21: =F20*0.1 -> 1824.9
A22: TOTAL INCLUDING GST | F22: =F20+F21 -> 20073.9
F25: Variation Raised By:
F26: AC
A28: ACCEPTED FOR AND ON BEHALF OF CLIENT: | F28: Authorised By:

Sheet VO6
A4: CONTRACT VARIATION - ESTIMATE
A6: PROJECT: | B6: ARCO | F6: Date: | G6: 45971
A7: NAME: | B7: Welink Construction | F7: Site Instruction / Ref:
A8: SITE ADDRESS: | B8: 22 - 24 Hood St, Subiaco
A9: JOB No: | B9: 1504
B11: VO6 - Tilt up panel design from Design Development to IFC
A12: Item | B12: Description | F12: Cost | G12: Credit
B13: Revised Panel Design from Design to IFC Drawings | C13: Qty | D13: Unit | E13: Rate ($)
A15: 1 | B15: Reinforcement changes from SL102 mesh EF (S00.07 Rev A) to N12-200 EF EW (S02.00 rev 0) | C15: 1 | D15: item | E15: 42780 | F15: =SUM(E15*1) -> 42780
A16: 2 | B16: Extra panel joints on Elevation 04 Grid 6-9 and Elevation 5 Grid G-E ( S14.01 Rev B to Rev 0) | C16: 1 | D16: item | E16: included above | F16: 0
A17: 3 | B17: Extra small panels on Elevation 03 L01 Grid G and Elevation 5 L01 Grid G | C17: 1 | D17: item | E17: included above | F17: 0
A18: 4 | B18: Detail change RBA16RI Spacing change from 1500mm(S00.07 Rev A) to 1000mm (S00.07 Rev 0) | C18: 1 | D18: item | E18: included above | F18: 0
A19: 5 | B19: Remove shiplap and baffle strip | C19: 1 | D19: item | E19: included above | F19: 0
A21: SUB TOTAL | F21: =SUM(F13:F20) -> 42780 | G21: =SUM(G13:G20) -> 0
A22: NETT VARIATION COST | F22: =F21-G21 -> 42780
A23: MARGIN AND OVERHEAD COSTS (10%) | F23: =F22*10% -> 4278
A24: VARIATION COST EXCLUDING GST | F24: =F22+F23 -> 47058
A25: GST | F25: =F24*0.1 -> 4705.8
A26: TOTAL INCLUDING GST | F26: =F24+F25 -> 51763.8
F29: Variation Raised By:
F30: AC
A32: ACCEPTED FOR AND ON BEHALF OF CLIENT: | F32: Authorised By:

Sheet VO7
A4: CONTRACT VARIATION - ESTIMATE
A6: PROJECT: | B6: ARCO | F6: Date: | G6: 45972
A7: NAME: | B7: Welink Construction | F7: Site Instruction / Ref:
A8: SITE ADDRESS: | B8: 22 - 24 Hood St, Subiaco
A9: JOB No: | B9: 1504
B11: VO7 - Panel rigging extra over from Design Development to IFC changes
A12: Item | B12: Description | F12: Cost | G12: Credit
B13: Additional Rigging and Caulking required for new Panel Design from Design to IFC | C13: Qty | D13: Unit | E13: Rate ($)
A15: 1 | B15: Panel rigging extra over due to additional panels from BP to IFC | C15: 1 | D15: item | E15: 20912 | F15: 20912
B16: Total panel quantity increased to 92 and panels requiring rotation with Franna has increased to 50. | F16: 0
F17: 0
B18: Additional Fire Mastic Jointing | C18: 1 | D18: item | E18: 2000 | F18: 2000
B19: Additional Steel Brackets | C19: 1 | D19: item | E19: 15480 | F19: 15480
A21: SUB TOTAL | F21: =SUM(F13:F20) -> 38392 | G21: =SUM(G13:G20) -> 0
A22: NETT VARIATION COST | F22: =F21-G21 -> 38392
A23: MARGIN AND OVERHEAD COSTS (10%) | F23: =F22*10% -> 3839.2
A24: VARIATION COST EXCLUDING GST | F24: =F22+F23 -> 42231.2
A25: GST | F25: =F24*0.1 -> 4223.12
A26: TOTAL INCLUDING GST | F26: =F24+F25 -> 46454.32
F29: Variation Raised By:
F30: AC
A32: ACCEPTED FOR AND ON BEHALF OF CLIENT: | F32: Authorised By:

Sheet VO8
A4: CONTRACT VARIATION - ESTIMATE
A6: PROJECT: | B6: ARCO | F6: Date: | G6: =TODAY() -> 46187
A7: NAME: | B7: Welink Construction | F7: Site Instruction / Ref:
A8: SITE ADDRESS: | B8: 22 - 24 Hood St, Subiaco
A9: JOB No: | B9: 1504
B11: VO8 - Additional waterproofing to lift pit and top of slab
A12: Item | B12: Description | F12: Cost | G12: Credit
B13: Updated Design from Design to IFC | C13: Qty | D13: Unit | E13: Rate ($)
A15: 1 | B15: Extend Enviro BSM waterproofing to lift pit and top of slab and upturn | C15: 1 | D15: item | E15: 15175 | F15: =SUM(E15*1) -> 15175
A16: 2 | B16: Original Allowance - Lift pit base and walls | C16: 1 | D16: item | E16: =1050+2590 -> 3640 | G16: =C16*E16 -> 3640
A18: SUB TOTAL | F18: =SUM(F13:F17) -> 15175 | G18: =SUM(G13:G17) -> 3640
A19: NETT VARIATION COST | F19: =F18-G18 -> 11535
A20: MARGIN AND OVERHEAD COSTS (10%) | F20: =F19*10% -> 1153.5
A21: VARIATION COST EXCLUDING GST | F21: =F19+F20 -> 12688.5
A22: GST | F22: =F21*0.1 -> 1268.85
A23: TOTAL INCLUDING GST | F23: =F21+F22 -> 13957.35
F26: Variation Raised By:
F27: AC
A29: ACCEPTED FOR AND ON BEHALF OF CLIENT: | F29: Authorised By:

Sheet VO9
A4: CONTRACT VARIATION - ESTIMATE
A6: PROJECT: | B6: ARCO | F6: Date: | G6: 46087
A7: NAME: | B7: Welink Construction | F7: Site Instruction / Ref:
A8: SITE ADDRESS: | B8: 22 - 24 Hood St, Subiaco
A9: JOB No: | B9: 1504
B11: VO9 - Electrical Design Changes from Design to IFC
A12: Item | B12: Description | F12: Cost | G12: Credit
C13: Qty | D13: Unit | E13: Rate ($)
A14: 1 | C14: 1 | D14: item | E14: 9165 | F14: =SUM(E14*1) -> 9165
A15: 2 | B15: Additional EV DB B2 | C15: 1 | D15: item | E15: incl | F15: incl
A16: 3 | B16: BWIC attendance | C16: 1 | D16: item | E16: 500 | F16: 500
A17: SUB TOTAL | F17: =SUM(F13:F16) -> 9665 | G17: =SUM(G13:G16) -> 0
A18: NETT VARIATION COST | F18: =F17-G17 -> 9665
A19: MARGIN AND OVERHEAD COSTS (10%) | F19: =F18*10% -> 966.5
A20: VARIATION COST EXCLUDING GST | F20: =F18+F19 -> 10631.5
A21: GST | F21: =F20*0.1 -> 1063.15
A22: TOTAL INCLUDING GST | F22: =F20+F21 -> 11694.65
F25: Variation Raised By:
F26: AC
F27: Amy Chen
A28: ACCEPTED FOR AND ON BEHALF OF CLIENT: | F28: Authorised By:

Sheet VO10
A4: CONTRACT VARIATION
A6: PROJECT: | B6: =Register!B4 -> ARCO | F6: Date: | G6: =TODAY() -> 46187
A7: NAME: | B7: Welink Construction | F7: Site Instruction / Ref:
A8: SITE ADDRESS: | B8: =Register!B5 -> 22 - 24 Hood St, Subiaco
A9: JOB No: | B9: =Register!B3 -> 1504
B11: VO10 - Mechanical Design Changes Design to IFC (Provisional)
A12: Item | B12: Description | F12: Cost | G12: Credit
C13: Qty | D13: Unit | E13: Rate ($)
A14: 1 | B14: Additional Ductwork due to clashes with Services | C14: 1 | D14: Item | E14: TBA | F14: =E14 -> TBA
A15: 2 | B15: Additional Plasteboard Bulkheads | C15: 1 | D15: item | E15: TBA | F15: =E15 -> TBA
F16: =E16 -> 0 | G16: =E16 -> 0
A41: SUB TOTAL | F41: =SUM(F13:F40) -> 0 | G41: =SUM(G13:G40) -> 0
A42: NETT VARIATION COST | F42: =SUM(F41) -> 0
A43: MARGIN AND OVERHEAD COSTS (10%) | F43: =F42*10% -> 0
A44: VARIATION COST EXCLUDING GST | F44: =F42+F43 -> 0
A45: GST | F45: =F44*0.1 -> 0
A46: TOTAL INCLUDING GST | F46: =F44+F45 -> 0
F49: Variation Raised By:
F50: AC
A52: ACCEPTED FOR AND ON BEHALF OF CLIENT: | F52: Authorised By:

Sheet VO11
A4: CONTRACT VARIATION
A6: PROJECT: | B6: =Register!B4 -> ARCO | F6: Date: | G6: =TODAY() -> 46187
A7: NAME: | B7: Welink Construction | F7: Site Instruction / Ref:
A8: SITE ADDRESS: | B8: =Register!B5 -> 22 - 24 Hood St, Subiaco
A9: JOB No: | B9: =Register!B3 -> 1504
B11: VO11 - Extra over cost for Car Stackers Prov Sum to Updated Design
A12: Item | B12: Description | F12: Cost | G12: Credit
C13: Qty | D13: Unit | E13: Rate ($)
A14: 1 | B14: Car Stacker price not included in original budget | C14: 1 | D14: item | E14: 325000 | F14: =E14 -> 325000 | G14: 191000
A15: 2 | B15: Builders Works/Protection/Spider Cranes | C15: 1 | D15: item | E15: 20000 | F15: =E15 -> 20000
B17: Budget as per QS report no design/quote previously avaiable.
A41: SUB TOTAL | F41: =SUM(F13:F40) -> 345000 | G41: =SUM(G13:G40) -> 191000
A42: NETT VARIATION COST | F42: =F41-G41 -> 154000
A43: MARGIN AND OVERHEAD COSTS (10%) | F43: =F42*10% -> 15400
A44: VARIATION COST EXCLUDING GST | F44: =F42+F43 -> 169400
A45: GST | F45: =F44*0.1 -> 16940
A46: TOTAL INCLUDING GST | F46: =F44+F45 -> 186340
F49: Variation Raised By:
F50: AC
A52: ACCEPTED FOR AND ON BEHALF OF CLIENT: | F52: Authorised By:

Sheet VO12
A4: CONTRACT VARIATION
A6: PROJECT: | B6: =Register!B4 -> ARCO | F6: Date: | G6: =TODAY() -> 46187
A7: NAME: | B7: Welink Construction | F7: Site Instruction / Ref:
A8: SITE ADDRESS: | B8: =Register!B5 -> 22 - 24 Hood St, Subiaco
A9: JOB No: | B9: =Register!B3 -> 1504
B11: VO12 - Concrete and Reo extras from Design to IFC Drawings
A12: Item | B12: Description | F12: Cost | G12: Credit
C13: Qty | D13: Unit | E13: Rate ($)
B14: Additional Concrete to Footings with Design Change to Basement | F14: =E14 -> 0
A15: 1 | B15: Formwork | G15: -11533
A16: 2 | B16: Concrete Additional Changes from BP to IFC | F16: 156992
A17: 3 | B17: Reinforcement Additional supply and install | F17: 41734.6
A18: 4 | B18: Shotcrete to Walls | F18: 49452.07
A20: SUB TOTAL | F20: =SUM(F13:F19) -> 248178.67 | G20: =SUM(G13:G19) -> -11533
A21: NETT VARIATION COST | F21: =F20+G20 -> 236645.67
A22: MARGIN AND OVERHEAD COSTS (10%) | F22: =F21*0.1 -> 23664.567
A23: VARIATION COST EXCLUDING GST | F23: =F21+F22 -> 260310.24
A24: GST | F24: =F23*0.1 -> 26031.024
A25: TOTAL INCLUDING GST | F25: =F23+F24 -> 286341.26
F28: Variation Raised By:
F29: AC
A31: ACCEPTED FOR AND ON BEHALF OF CLIENT: | F31: Authorised By:

Sheet VO13
A4: CONTRACT VARIATION
A6: PROJECT: | B6: =Register!B4 -> ARCO | F6: Date: | G6: =TODAY() -> 46187
A7: NAME: | B7: Welink Construction | F7: Site Instruction / Ref:
A8: SITE ADDRESS: | B8: =Register!B5 -> 22 - 24 Hood St, Subiaco
A9: JOB No: | B9: =Register!B3 -> 1504
B11: VO13 - Buildability Issue and Latent Ground Conditions
A12: Item | B12: Description | F12: Cost | G12: Credit
C13: Qty | D13: Unit | E13: Rate ($)
B14: Latent Condition to Ground necessited Grout infill to Piles
A15: 1 | B15: Grouting to Boundary due to Latent Condition with soil | F15: 47500
A17: 2 | B17: Omit Block Wall GL G | F17: 0 | G17: -25000
A18: 3 | B18: Piling to GL G | F18: 138000
A19: 4 | B19: Shotcrete to Piles Wall | F19: 49452
A20: SUB TOTAL | F20: =SUM(F13:F19) -> 234952 | G20: =SUM(G13:G19) -> -25000
A21: NETT VARIATION COST | F21: =F20+G20 -> 209952
A22: MARGIN AND OVERHEAD COSTS (10%) | F22: =F21*0.1 -> 20995.2
A23: VARIATION COST EXCLUDING GST | F23: =F21+F22 -> 230947.2
A24: GST | F24: =F23*0.1 -> 23094.72
A25: TOTAL INCLUDING GST | F25: =F23+F24 -> 254041.92
F28: Variation Raised By:
F29: AC
A31: ACCEPTED FOR AND ON BEHALF OF CLIENT: | F31: Authorised By:

Sheet VO14
A4: CONTRACT VARIATION
A6: PROJECT: | B6: ARCO | F6: Date: | G6: =TODAY() -> 46187
A7: NAME: | B7: Welink Construction | F7: Site Instruction / Ref:
A8: SITE ADDRESS: | B8: 22 - 24 Hood St, Subiaco
A9: JOB No: | B9: 1504
B11: VO14 - Client Upgrade Items as per Schedule
A12: Item | B12: Description | F12: Cost | G12: Credit
A13: Unit No | B13: Upgrade cost items as per Schedule | C13: Qty | D13: Unit | E13: Rate ($)
A14: 101 | B14: Herringbone Engineered Floor Boards | C14: 1 | D14: ITEM | E14: 6250 | F14: =C14*E14 -> 6250
B15: x2 Vertical Heated Towel Rails | C15: 1 | D15: ITEM | E15: 2480 | F15: =C15*E15 -> 2480
B16: Feature Pendant Light (Coral Linear Rod) | C16: 1 | D16: ITEM | E16: 1750 | F16: =C16*E16 -> 1750
A17: 102 | B17: Feature Pendant Light | C17: 1 | D17: ITEM | E17: 1750 | F17: =C17*E17 -> 1750
B18: Feature Light (Pair) | C18: 1 | D18: ITEM | E18: 580 | F18: =C18*E18 -> 580
B19: Semi-Integrated Dishwasher | C19: 1 | D19: ITEM | E19: 3450 | F19: =C19*E19 -> 3450
B20: Microwave | C20: 1 | D20: ITEM | E20: 3649 | F20: =C20*E20 -> 3649
A21: 201 | B21: Herringbone Engineered Floor Boards | C21: 1 | D21: ITEM | E21: 6250 | F21: =C21*E21 -> 6250
B22: Pendant Kitchen Light | C22: 1 | D22: ITEM | E22: 1750 | F22: =C22*E22 -> 1750
A23: 204 | B23: Herringbone Engineered Floor boards | C23: 1 | D23: ITEM | E23: 6250 | F23: =C23*E23 -> 6250
B24: Integrated Dishwasher | C24: 1 | D24: ITEM | E24: 3450 | F24: =C24*E24 -> 3450
B25: Built-in Integrated Fridge & Freezer | C25: 1 | D25: ITEM | E25: 8590 | F25: =C25*E25 -> 8590
A26: 308 | B26: Integrated Dishwasher | C26: 1 | D26: ITEM | E26: 3450 | F26: =C26*E26 -> 3450
C27: 1 | D27: ITEM | F27: =C27*E27 -> 0
B28: Built-in Integrated Fridge & Freezer | C28: 1 | D28: ITEM | E28: 8590 | F28: =C28*E28 -> 8590
B29: Integrated Microwave | C29: 1 | D29: ITEM | E29: 3649 | F29: =C29*E29 -> 3649
A30: 402 | B30: Herringbone Engineered Floor Boards - French Oak to Living & Kitchen | C30: 1 | D30: ITEM | E30: 6250 | F30: =C30*E30 -> 6250
B31: Built-in Integrated Fridge & Freezer - Fisher & Paykel RS90A1 476L | C31: 1 | D31: ITEM | E31: 8590 | F31: =C31*E31 -> 8590
B32: Feature Pendant Light - Generic | C32: 1 | D32: ITEM | E32: 1750 | F32: =C32*E32 -> 1750
A33: 403 | B33: Engineered Floor Boards | C33: 1 | D33: ITEM | E33: 6250 | F33: =C33*E33 -> 6250
B34: Drawers | C34: 1 | D34: ITEM | E34: 2750 | F34: =C34*E34 -> 2750
B35: Feature Pendant Light | C35: 1 | D35: ITEM | E35: 1750 | F35: =C35*E35 -> 1750
A36: 404 | B36: Integrated Dishwasher | C36: 1 | D36: ITEM | E36: 3450 | F36: =C36*E36 -> 3450
B37: Integrated Fridge & Freezer | C37: 1 | D37: ITEM | E37: 8590 | F37: =C37*E37 -> 8590
B38: Washing Machine | C38: 1 | D38: ITEM | E38: 1649 | F38: =C38*E38 -> 1649
B39: x2 Heated Towel Rails | C39: 1 | D39: ITEM | E39: 2480 | F39: =C39*E39 -> 2480
B40: Drawers | C40: 1 | D40: ITEM | E40: 2750 | F40: =C40*E40 -> 2750
A41: 407 | B41: Washing Machine | C41: 1 | D41: ITEM | E41: 1649 | F41: =C41*E41 -> 1649
B42: Drawers | C42: 1 | D42: ITEM | E42: 2750 | F42: =C42*E42 -> 2750
A43: 601 | B43: Engineered Herringbone Floor Boards | C43: 1 | D43: ITEM | E43: 6250 | F43: =C43*E43 -> 6250
B44: Feature Pendant Light | C44: 1 | D44: ITEM | E44: 1750 | F44: =C44*E44 -> 1750
A45: 602 | B45: Herringbone Engineered Floor Boards | C45: 1 | D45: ITEM | E45: 6250 | F45: =C45*E45 -> 6250
...

Sheet VO15
A4: CONTRACT VARIATION
A6: PROJECT: | B6: =Register!B4 -> ARCO | F6: Date: | G6: =TODAY() -> 46187
A7: NAME: | B7: Welink Construction | F7: Site Instruction / Ref:
A8: SITE ADDRESS: | B8: =Register!B5 -> 22 - 24 Hood St, Subiaco
A9: JOB No: | B9: =Register!B3 -> 1504
B11: VO15 - Extra over grout and reinforcememt to precat panel base 100mm
A12: Item | B12: Description | F12: Cost | G12: Credit
C13: Qty | D13: Unit | E13: Rate ($)
A14: 1 | F14: =C14*E14 -> 0
A15: 2
A16: 3
A17: 4
A19: SUB TOTAL | F19: =SUM(F13:F18) -> 0 | G19: =SUM(G13:G18) -> 0
A20: NETT VARIATION COST | F20: =F19+G19 -> 0
A21: MARGIN AND OVERHEAD COSTS (10%) | F21: =F20*0.1 -> 0
A22: VARIATION COST EXCLUDING GST | F22: =F20+F21 -> 0
A23: GST | F23: =F22*0.1 -> 0
A24: TOTAL INCLUDING GST | F24: =F22+F23 -> 0
F27: Variation Raised By:
F28: AC
A30: ACCEPTED FOR AND ON BEHALF OF CLIENT: | F30: Authorised By:

Sheet VO16
A4: CONTRACT VARIATION
A6: PROJECT: | B6: =Register!B4 -> ARCO | F6: Date: | G6: =TODAY() -> 46187
A7: NAME: | B7: Welink Construction | F7: Site Instruction / Ref:
A8: SITE ADDRESS: | B8: =Register!B5 -> 22 - 24 Hood St, Subiaco
A9: JOB No: | B9: =Register!B3 -> 1504
B11: VO16 - Extra monorail on ground floor
A12: Item | B12: Description | F12: Cost | G12: Credit
C13: Qty | D13: Unit | E13: Rate ($)
A14: 1 | F14: =C14*E14 -> 0
A15: 2
A16: 3
A17: 4
A19: SUB TOTAL | F19: =SUM(F13:F18) -> 0 | G19: =SUM(G13:G18) -> 0
A20: NETT VARIATION COST | F20: =F19+G19 -> 0
A21: MARGIN AND OVERHEAD COSTS (10%) | F21: =F20*0.1 -> 0
A22: VARIATION COST EXCLUDING GST | F22: =F20+F21 -> 0
A23: GST | F23: =F22*0.1 -> 0
A24: TOTAL INCLUDING GST | F24: =F22+F23 -> 0
F27: Variation Raised By:
F28: AC
A30: ACCEPTED FOR AND ON BEHALF OF CLIENT: | F30: Authorised By:

Sheet VOXX
A4: CONTRACT VARIATION
A6: PROJECT: | B6: =Register!B4 -> ARCO | F6: Date: | G6: =TODAY() -> 46187
A7: NAME: | B7: Welink Construction | F7: Site Instruction / Ref:
A8: SITE ADDRESS: | B8: =Register!B5 -> 22 - 24 Hood St, Subiaco
A9: JOB No: | B9: =Register!B3 -> 1504
B11: VO
A12: Item | B12: Description | F12: Cost | G12: Credit
C13: Qty | D13: Unit | E13: Rate ($)
A14: 1 | F14: =C14*E14 -> 0
A15: 2
A16: 3
A17: 4
A19: SUB TOTAL | F19: =SUM(F13:F18) -> 0 | G19: =SUM(G13:G18) -> 0
A20: NETT VARIATION COST | F20: =F19+G19 -> 0
A21: MARGIN AND OVERHEAD COSTS (10%) | F21: =F20*0.1 -> 0
A22: VARIATION COST EXCLUDING GST | F22: =F20+F21 -> 0
A23: GST | F23: =F22*0.1 -> 0
A24: TOTAL INCLUDING GST | F24: =F22+F23 -> 0
F27: Variation Raised By:
F28: AC
A30: ACCEPTED FOR AND ON BEHALF OF CLIENT: | F30: Authorised By:

Sheet Register
A1: Variation Register | M1: =TODAY() -> 46187
A3: Job #: | B3: 1504 | E3: BASE CONTRACT AMOUNT | G3: 28198978
A4: Project: | B4: ARCO | E4: TOTAL VARIATIONS APPROVED TO DATE | G4: =G38-G5 -> 862182.74 | M4: Submitted
A5: Location: | B5: 22 - 24 Hood St, Subiaco | E5: SUBTOTAL PSUMS TO DATE | G5: =G17+G25 -> 249196.2 | M5: Approved
E6: SUBTOTAL CONTRACT TO DATE | G6: =SUM(G3:G5) -> 29310357 | M6: Void
E7: PENDING | G7: =E38 -> 361582.1 | M7: Rejected
E8: IN DISPUTE | G8: =F38 -> 0
E9: PROJECTED CONTRACT TOTAL | G9: =SUM(G6:G8) -> 29671939
A12: VO# | B12: DESCRIPTION | C12: DATE VO ISSUED | D12: VARIATION VALUE | E12: PENDING APPROVAL | F12: NOT APPROVED | G12: TOTAL APPROVED | H12: NOT PROCEEDING | I12: IN DISPUTE | J12: NOD / EOT | K12: STATUS | L12: NOTES | M12: Action
A13: 1 | B13: ='VO1'!B11 -> VO1 - Wet Fire Variation to Ground Floor | C13: 45882 | D13: ='VO1'!F26 -> 71159 | E13: =D13-G13 -> 0 | F13: =D13-G13-E13 -> 0 | G13: 71159 | K13: Approved | L13: Head Contract VO | M13: PS
A14: 2 | B14: ='VO2'!B11 -> VO2 - Upgrade to 50 dia supply Water to Ground floor | C14: 45882 | D14: ='VO2'!F21 -> 25795 | E14: =D14-G14 -> 0 | F14: =D14-G14-E14 -> 0 | G14: 25795 | K14: Approved | L14: Head Contract VO | M14: PS
A15: 3 | B15: ='VO3'!B11 -> VO3 - Earthworks - additional backfill & testing | C15: 45882 | D15: ='VO3'!F21 -> 76780 | E15: =D15-G15 -> 0 | F15: =D15-G15-E15 -> 0 | G15: 76780 | K15: Approved | L15: Head Contract VO | M15: PS
A16: 4 | B16: ='VO4'!B11 -> VO4 - Site Amenities - Lease | C16: 45882 | D16: ='VO4'!F21 -> 330000 | E16: =D16-G16 -> 0 | F16: =D16-G16-E16 -> 0 | G16: 330000 | K16: Approved | L16: Head Contract VO | M16: PS
A17: 5 | B17: ='VO5'!B11 -> VO5 - Fire Services IFC Updates | C17: 45882 | D17: ='VO5'!F20 -> 18249 | E17: =D17-G17 -> 0 | F17: =D17-G17-E17 -> 0 | G17: 18249 | K17: Approved | L17: Head Contract VO | M17: PS
A18: 6 | B18: ='VO6'!B11 -> VO6 - Tilt up panel design from Design Development to IFC | C18: 45971 | D18: ='VO6'!F24 -> 47058 | E18: =D18-G18 -> 0 | F18: =D18-G18-E18 -> 0 | G18: 47058 | K18: Approved for Signing | L18: Head Contract VO | M18: PS
A19: 7 | B19: ='VO7'!$B11 -> VO7 - Panel rigging extra over from Design Development to IFC changes | C19: 45972 | D19: 38392 | E19: =D19-G19 -> 0 | F19: =D19-G19-E19 -> 0 | G19: 38392 | K19: Approved for Signing | L19: Head Contract VO | M19: PS
A20: 8 | B20: ='VO8'!$B11 -> VO8 - Additional waterproofing to lift pit and top of slab | C20: 45993 | D20: ='VO8'!F21 -> 12688.5 | E20: =D20-G20 -> 0 | F20: =D20-G20-E20 -> 0 | G20: 12688.5 | K20: Approved | L20: Head Contract VO | M20: PS
A21: 9 | B21: ='VO9'!$B11 -> VO9 - Electrical Design Changes from Design to IFC | C21: 46087 | D21: ='VO9'!F20 -> 10631.5 | E21: 10631.5 | F21: =D21-G21-E21 -> 0 | G21: 0 | K21: Submitted | L21: Head Contract VO
A22: 10 | B22: ='VO10'!B11 -> VO10 - Mechanical Design Changes Design to IFC (Provisional) | C22: 46087 | D22: TBA | E22: TBA | F22: TBA | G22: 0 | K22: Submitted | L22: Head Contract VO
A23: 11 | B23: ='VO11'!$B11 -> VO11 - Extra over cost for Car Stackers Prov Sum to Updated Design | C23: 46087 | D23: ='VO11'!F44 -> 169400 | E23: =D23 -> 169400 | F23: =D23-G23-E23 -> 0 | G23: 0 | K23: Submitted | L23: Head Contract VO
A24: 12 | B24: ='VO12'!$B11 -> VO12 - Concrete and Reo extras from Design to IFC Drawings | C24: 46087 | D24: ='VO12'!F23 -> 260310.24 | E24: =D24-G24 -> -0.003 | F24: =D24-G24-E24 -> 0 | G24: 260310.24 | K24: Approved | L24: Head Contract VO | M24: Completed works
A25: 13 | B25: ='VO13'!$B11 -> VO13 - Buildability Issue and Latent Ground Conditions | C25: 46087 | D25: ='VO13'!F23 -> 230947.2 | E25: =D25-G25 -> 0 | F25: =D25-G25-E25 -> 0 | G25: 230947.2 | K25: Approved | L25: Head Contract VO | M25: Completed works
A26: 14 | B26: ='VO14'!B11 -> VO14 - Client Upgrade Items as per Schedule | C26: ='VO14'!G6 -> 46187 | D26: ='VO14'!F62 -> 181550.6 | E26: =D26 -> 181550.6 | F26: =D26-G26-E26 -> 0 | G26: 0 | K26: Submitted | L26: Head Contract VO
A27: 15 | B27: ='VO15'!B11 -> VO15 - Extra over grout and reinforcememt to precat panel base 100mm | C27: ='VO15'!G6 -> 46187 | D27: ='VO15'!F22 -> 0 | E27: =D27 -> 0 | F27: =D27-G27-E27 -> 0 | G27: 0 | L27: Head Contract VO
A28: 16 | B28: ='VO16'!B11 -> VO16 - Extra monorail on ground floor | C28: ='VO16'!G6 -> 46187 | D28: ='VO16'!F22 -> 0 | E28: =D28 -> 0 | F28: =D28-G28-E28 -> 0 | G28: 0 | L28: Head Contract VO
A29: 17
A30: 18
A31: 19
A32: 20
A33: 21
A34: 22
A35: 23
B38: TOTALS | D38: =SUM(D13:D37) -> 1472961 | E38: =SUM(E13:E37) -> 361582.1 | F38: =SUM(F13:F37) -> 0 | G38: =SUM(G13:G37) -> 1111378.9 | H38: =SUM(H13:H37) -> 0 | I38: =SUM(I13:I37) -> 0 | L38: =G13+G15+G17+G23+G25+G27+G28+G29 -> 397135.2
L39: =L38 -> 397135.2 | M39: Head Contract VO
L40: =G38-L38 -> 714243.74 | M40: Client Direct VO
L41: =SUM(L39:L40) -> 1111378.9
L42: =G3 -> 28198978 | M42: Contract Sum
L43: =L41+L42 -> 29310357 | M43: Adjusted Contract Sum
L44: =G9 -> 29671939 | M44: PROJECTED CONTRACT SUM

Sheet Internal VO Register
A1: Variation Register | G1: =TODAY() -> 46187
A3: VO# | B3: DESCRIPTION | C3: VARIATION VALUE | D3: BANK APPROVED | E3: Client Approved | F3: Pending | G3: NOTES
A4: 1 | J4: Head Contract VO
A5: 2 | B5: VO1 - Wet Fire Variation to Ground Floor | C5: 71159 | E5: 71159 | J5: Client Direct VO
A6: 3 | B6: VO2 - Upgrade to 50 dia supply Water to Ground floor | C6: 25795 | E6: 25795
A7: 4 | B7: VO3 - Earthworks - additional backfill & testing | C7: 76780 | E7: 76780
A8: 5 | B8: VO4 - Site Amenities - Lease | C8: 330000 | E8: 330000
A9: 6 | B9: VO5 - Fire Services IFC Updates | C9: 18249 | E9: 18249
A10: 7 | B10: VO6 - Tilt up panel design BP to IFC | C10: 47058 | E10: 47058
A11: 8 | B11: VO7 - Panel rigging extra over from Design Development to IFC changes | C11: 38392 | E11: 38392
A12: 9 | B12: VO8 - Additional waterproofing to lift pit and top of slab | C12: 6336 | E12: 6336
A13: 10 | B13: VO9 - Electrical Design Changes from Design to IFC | C13: 10631.5
A14: 11 | B14: VO10 - Mechanical Design Changes Design to IFC (Provisional) | C14: TBA
A15: 12 | B15: VO11 - Car Stackers not included in Contract | C15: 169400
A16: 13 | B16: VO12 - Concrete and Reo extras from Design to IFC Drawings | C16: 260310.24
A17: 14 | B17: VO13 - Buildability Issue and Latent Ground Conditions | C17: 230947.2
B21: TOTALS | C21: =SUM(C4:C20) -> 1285057.9 | D21: =SUM(D4:D20) -> 0 | E21: =SUM(E4:E20) -> 613769 | F21: =SUM(F4:F20) -> 0 | G21: =D21+E21 -> 613769
